2022-11-11 17:20:28,768 INFO    MainThread:11784 [wandb_setup.py:_flush():68] Configure stats pid to 11784
2022-11-11 17:20:28,768 INFO    MainThread:11784 [wandb_setup.py:_flush():68] Loading settings from C:\Users\Zabraf\.config\wandb\settings
2022-11-11 17:20:28,769 INFO    MainThread:11784 [wandb_setup.py:_flush():68] Loading settings from C:\Users\Zabraf\Documents\Github\TB_DQN_A2C_CartePole\wandb\settings
2022-11-11 17:20:28,769 INFO    MainThread:11784 [wandb_setup.py:_flush():68] Loading settings from environment variables: {'_require_service': 'True'}
2022-11-11 17:20:28,769 INFO    MainThread:11784 [wandb_setup.py:_flush():68] Inferring run settings from compute environment: {'program_relpath': 'PytorchA2C.py', 'program': 'c:\\Users\\Zabraf\\Documents\\Github\\TB_DQN_A2C_CartePole\\PytorchA2C.py'}
2022-11-11 17:20:28,770 INFO    MainThread:11784 [wandb_init.py:_log_setup():476] Logging user logs to C:\Users\Zabraf\Documents\Github\TB_DQN_A2C_CartePole\wandb\run-20221111_172028-31v1bspp\logs\debug.log
2022-11-11 17:20:28,771 INFO    MainThread:11784 [wandb_init.py:_log_setup():477] Logging internal logs to C:\Users\Zabraf\Documents\Github\TB_DQN_A2C_CartePole\wandb\run-20221111_172028-31v1bspp\logs\debug-internal.log
2022-11-11 17:20:28,771 INFO    MainThread:11784 [wandb_init.py:init():516] calling init triggers
2022-11-11 17:20:28,771 INFO    MainThread:11784 [wandb_init.py:init():519] wandb.init called with sweep_config: {}
config: {}
2022-11-11 17:20:28,771 INFO    MainThread:11784 [wandb_init.py:init():569] starting backend
2022-11-11 17:20:28,771 INFO    MainThread:11784 [wandb_init.py:init():573] setting up manager
2022-11-11 17:20:28,773 INFO    MainThread:11784 [backend.py:_multiprocessing_setup():102] multiprocessing start_methods=spawn, using: spawn
2022-11-11 17:20:28,776 INFO    MainThread:11784 [wandb_init.py:init():580] backend started and connected
2022-11-11 17:20:28,777 INFO    MainThread:11784 [wandb_init.py:init():658] updated telemetry
2022-11-11 17:20:28,817 INFO    MainThread:11784 [wandb_init.py:init():692] communicating run to backend with 30 second timeout
2022-11-11 17:20:38,881 WARNING MainThread:11784 [wandb_init.py:init():1097] interrupted
Traceback (most recent call last):
  File "C:\Users\Zabraf\AppData\Local\Programs\Python\Python310\lib\site-packages\wandb\sdk\wandb_init.py", line 1076, in init
    run = wi.init()
  File "C:\Users\Zabraf\AppData\Local\Programs\Python\Python310\lib\site-packages\wandb\sdk\wandb_init.py", line 696, in init
    result = handle.wait(
  File "C:\Users\Zabraf\AppData\Local\Programs\Python\Python310\lib\site-packages\wandb\sdk\lib\mailbox.py", line 76, in wait
    found = self._slot._get_and_clear(timeout=1)
  File "C:\Users\Zabraf\AppData\Local\Programs\Python\Python310\lib\site-packages\wandb\sdk\lib\mailbox.py", line 35, in _get_and_clear
    if self._event.wait(timeout=timeout):
  File "C:\Users\Zabraf\AppData\Local\Programs\Python\Python310\lib\threading.py", line 600, in wait
    signaled = self._cond.wait(timeout)
  File "C:\Users\Zabraf\AppData\Local\Programs\Python\Python310\lib\threading.py", line 324, in wait
    gotit = waiter.acquire(True, timeout)
KeyboardInterrupt
2022-11-11 17:20:39,422 ERROR   Thread-7 (wrapped_target):11784 [retry.py:__call__():154] Retry attempt failed:
Traceback (most recent call last):
  File "C:\Users\Zabraf\AppData\Local\Programs\Python\Python310\lib\site-packages\urllib3\connection.py", line 174, in _new_conn
    conn = connection.create_connection(
  File "C:\Users\Zabraf\AppData\Local\Programs\Python\Python310\lib\site-packages\urllib3\util\connection.py", line 95, in create_connection
    raise err
  File "C:\Users\Zabraf\AppData\Local\Programs\Python\Python310\lib\site-packages\urllib3\util\connection.py", line 85, in create_connection
    sock.connect(sa)
ConnectionRefusedError: [WinError 10061] Aucune connexion n’a pu être établie car l’ordinateur cible l’a expressément refusée

During handling of the above exception, another exception occurred:

Traceback (most recent call last):
  File "C:\Users\Zabraf\AppData\Local\Programs\Python\Python310\lib\site-packages\urllib3\connectionpool.py", line 703, in urlopen
    httplib_response = self._make_request(
  File "C:\Users\Zabraf\AppData\Local\Programs\Python\Python310\lib\site-packages\urllib3\connectionpool.py", line 398, in _make_request
    conn.request(method, url, **httplib_request_kw)
  File "C:\Users\Zabraf\AppData\Local\Programs\Python\Python310\lib\site-packages\urllib3\connection.py", line 239, in request
    super(HTTPConnection, self).request(method, url, body=body, headers=headers)
  File "C:\Users\Zabraf\AppData\Local\Programs\Python\Python310\lib\http\client.py", line 1282, in request
    self._send_request(method, url, body, headers, encode_chunked)
  File "C:\Users\Zabraf\AppData\Local\Programs\Python\Python310\lib\http\client.py", line 1328, in _send_request
    self.endheaders(body, encode_chunked=encode_chunked)
  File "C:\Users\Zabraf\AppData\Local\Programs\Python\Python310\lib\http\client.py", line 1277, in endheaders
    self._send_output(message_body, encode_chunked=encode_chunked)
  File "C:\Users\Zabraf\AppData\Local\Programs\Python\Python310\lib\http\client.py", line 1037, in _send_output
    self.send(msg)
  File "C:\Users\Zabraf\AppData\Local\Programs\Python\Python310\lib\http\client.py", line 975, in send
    self.connect()
  File "C:\Users\Zabraf\AppData\Local\Programs\Python\Python310\lib\site-packages\urllib3\connection.py", line 205, in connect
    conn = self._new_conn()
  File "C:\Users\Zabraf\AppData\Local\Programs\Python\Python310\lib\site-packages\urllib3\connection.py", line 186, in _new_conn
    raise NewConnectionError(
urllib3.exceptions.NewConnectionError: <urllib3.connection.HTTPConnection object at 0x000002A46549FD90>: Failed to establish a new connection: [WinError 10061] Aucune connexion n’a pu être établie car l’ordinateur cible l’a expressément refusée

During handling of the above exception, another exception occurred:

Traceback (most recent call last):
  File "C:\Users\Zabraf\AppData\Local\Programs\Python\Python310\lib\site-packages\requests\adapters.py", line 489, in send
    resp = conn.urlopen(
  File "C:\Users\Zabraf\AppData\Local\Programs\Python\Python310\lib\site-packages\urllib3\connectionpool.py", line 787, in urlopen
    retries = retries.increment(
  File "C:\Users\Zabraf\AppData\Local\Programs\Python\Python310\lib\site-packages\urllib3\util\retry.py", line 592, in increment
    raise MaxRetryError(_pool, url, error or ResponseError(cause))
urllib3.exceptions.MaxRetryError: HTTPConnectionPool(host='localhost', port=8080): Max retries exceeded with url: /graphql (Caused by NewConnectionError('<urllib3.connection.HTTPConnection object at 0x000002A46549FD90>: Failed to establish a new connection: [WinError 10061] Aucune connexion n’a pu être établie car l’ordinateur cible l’a expressément refusée'))

During handling of the above exception, another exception occurred:

Traceback (most recent call last):
  File "C:\Users\Zabraf\AppData\Local\Programs\Python\Python310\lib\site-packages\wandb\sdk\lib\retry.py", line 113, in __call__
    result = self._call_fn(*args, **kwargs)
  File "C:\Users\Zabraf\AppData\Local\Programs\Python\Python310\lib\site-packages\wandb\sdk\internal\internal_api.py", line 199, in execute
    return self.client.execute(*args, **kwargs)  # type: ignore
  File "C:\Users\Zabraf\AppData\Local\Programs\Python\Python310\lib\site-packages\wandb\vendor\gql-0.2.0\wandb_gql\client.py", line 52, in execute
    result = self._get_result(document, *args, **kwargs)
  File "C:\Users\Zabraf\AppData\Local\Programs\Python\Python310\lib\site-packages\wandb\vendor\gql-0.2.0\wandb_gql\client.py", line 60, in _get_result
    return self.transport.execute(document, *args, **kwargs)
  File "C:\Users\Zabraf\AppData\Local\Programs\Python\Python310\lib\site-packages\wandb\vendor\gql-0.2.0\wandb_gql\transport\requests.py", line 38, in execute
    request = requests.post(self.url, **post_args)
  File "C:\Users\Zabraf\AppData\Local\Programs\Python\Python310\lib\site-packages\requests\api.py", line 115, in post
    return request("post", url, data=data, json=json, **kwargs)
  File "C:\Users\Zabraf\AppData\Local\Programs\Python\Python310\lib\site-packages\requests\api.py", line 59, in request
    return session.request(method=method, url=url, **kwargs)
  File "C:\Users\Zabraf\AppData\Local\Programs\Python\Python310\lib\site-packages\requests\sessions.py", line 587, in request
    resp = self.send(prep, **send_kwargs)
  File "C:\Users\Zabraf\AppData\Local\Programs\Python\Python310\lib\site-packages\requests\sessions.py", line 701, in send
    r = adapter.send(request, **kwargs)
  File "C:\Users\Zabraf\AppData\Local\Programs\Python\Python310\lib\site-packages\requests\adapters.py", line 565, in send
    raise ConnectionError(e, request=request)
requests.exceptions.ConnectionError: HTTPConnectionPool(host='localhost', port=8080): Max retries exceeded with url: /graphql (Caused by NewConnectionError('<urllib3.connection.HTTPConnection object at 0x000002A46549FD90>: Failed to establish a new connection: [WinError 10061] Aucune connexion n’a pu être établie car l’ordinateur cible l’a expressément refusée'))
2022-11-11 17:20:58,620 WARNING MsgRouterThr:11784 [router.py:message_loop():77] message_loop has been closed
