2022-11-11 17:20:28,781 INFO    StreamThr :14200 [internal.py:wandb_internal():88] W&B internal server running at pid: 14200, started at: 2022-11-11 17:20:28.780649
2022-11-11 17:20:28,782 DEBUG   HandlerThread:14200 [handler.py:handle_request():138] handle_request: status
2022-11-11 17:20:28,784 DEBUG   SenderThread:14200 [sender.py:send_request():315] send_request: status
2022-11-11 17:20:28,786 DEBUG   SenderThread:14200 [sender.py:send():301] send: header
2022-11-11 17:20:28,786 INFO    WriterThread:14200 [datastore.py:open_for_write():75] open: C:\Users\Zabraf\Documents\Github\TB_DQN_A2C_CartePole\wandb\run-20221111_172028-31v1bspp\run-31v1bspp.wandb
2022-11-11 17:20:28,818 DEBUG   SenderThread:14200 [sender.py:send():301] send: run
2022-11-11 17:20:38,890 DEBUG   HandlerThread:14200 [handler.py:handle_request():138] handle_request: poll_exit
2022-11-11 17:20:43,998 DEBUG   HandlerThread:14200 [handler.py:handle_request():138] handle_request: poll_exit
2022-11-11 17:20:44,462 ERROR   SenderThread:14200 [retry.py:__call__():154] Retry attempt failed:
Traceback (most recent call last):
  File "C:\Users\Zabraf\AppData\Local\Programs\Python\Python310\lib\site-packages\urllib3\connection.py", line 174, in _new_conn
    conn = connection.create_connection(
  File "C:\Users\Zabraf\AppData\Local\Programs\Python\Python310\lib\site-packages\urllib3\util\connection.py", line 95, in create_connection
    raise err
  File "C:\Users\Zabraf\AppData\Local\Programs\Python\Python310\lib\site-packages\urllib3\util\connection.py", line 85, in create_connection
    sock.connect(sa)
ConnectionRefusedError: [WinError 10061] Aucune connexion n’a pu être établie car l’ordinateur cible l’a expressément refusée

During handling of the above exception, another exception occurred:

Traceback (most recent call last):
  File "C:\Users\Zabraf\AppData\Local\Programs\Python\Python310\lib\site-packages\urllib3\connectionpool.py", line 703, in urlopen
    httplib_response = self._make_request(
  File "C:\Users\Zabraf\AppData\Local\Programs\Python\Python310\lib\site-packages\urllib3\connectionpool.py", line 398, in _make_request
    conn.request(method, url, **httplib_request_kw)
  File "C:\Users\Zabraf\AppData\Local\Programs\Python\Python310\lib\site-packages\urllib3\connection.py", line 239, in request
    super(HTTPConnection, self).request(method, url, body=body, headers=headers)
  File "C:\Users\Zabraf\AppData\Local\Programs\Python\Python310\lib\http\client.py", line 1282, in request
    self._send_request(method, url, body, headers, encode_chunked)
  File "C:\Users\Zabraf\AppData\Local\Programs\Python\Python310\lib\http\client.py", line 1328, in _send_request
    self.endheaders(body, encode_chunked=encode_chunked)
  File "C:\Users\Zabraf\AppData\Local\Programs\Python\Python310\lib\http\client.py", line 1277, in endheaders
    self._send_output(message_body, encode_chunked=encode_chunked)
  File "C:\Users\Zabraf\AppData\Local\Programs\Python\Python310\lib\http\client.py", line 1037, in _send_output
    self.send(msg)
  File "C:\Users\Zabraf\AppData\Local\Programs\Python\Python310\lib\http\client.py", line 975, in send
    self.connect()
  File "C:\Users\Zabraf\AppData\Local\Programs\Python\Python310\lib\site-packages\urllib3\connection.py", line 205, in connect
    conn = self._new_conn()
  File "C:\Users\Zabraf\AppData\Local\Programs\Python\Python310\lib\site-packages\urllib3\connection.py", line 186, in _new_conn
    raise NewConnectionError(
urllib3.exceptions.NewConnectionError: <urllib3.connection.HTTPConnection object at 0x0000024E180B5810>: Failed to establish a new connection: [WinError 10061] Aucune connexion n’a pu être établie car l’ordinateur cible l’a expressément refusée

During handling of the above exception, another exception occurred:

Traceback (most recent call last):
  File "C:\Users\Zabraf\AppData\Local\Programs\Python\Python310\lib\site-packages\requests\adapters.py", line 489, in send
    resp = conn.urlopen(
  File "C:\Users\Zabraf\AppData\Local\Programs\Python\Python310\lib\site-packages\urllib3\connectionpool.py", line 787, in urlopen
    retries = retries.increment(
  File "C:\Users\Zabraf\AppData\Local\Programs\Python\Python310\lib\site-packages\urllib3\util\retry.py", line 592, in increment
    raise MaxRetryError(_pool, url, error or ResponseError(cause))
urllib3.exceptions.MaxRetryError: HTTPConnectionPool(host='localhost', port=8080): Max retries exceeded with url: /graphql (Caused by NewConnectionError('<urllib3.connection.HTTPConnection object at 0x0000024E180B5810>: Failed to establish a new connection: [WinError 10061] Aucune connexion n’a pu être établie car l’ordinateur cible l’a expressément refusée'))

During handling of the above exception, another exception occurred:

Traceback (most recent call last):
  File "C:\Users\Zabraf\AppData\Local\Programs\Python\Python310\lib\site-packages\wandb\sdk\lib\retry.py", line 113, in __call__
    result = self._call_fn(*args, **kwargs)
  File "C:\Users\Zabraf\AppData\Local\Programs\Python\Python310\lib\site-packages\wandb\sdk\internal\internal_api.py", line 199, in execute
    return self.client.execute(*args, **kwargs)  # type: ignore
  File "C:\Users\Zabraf\AppData\Local\Programs\Python\Python310\lib\site-packages\wandb\vendor\gql-0.2.0\wandb_gql\client.py", line 52, in execute
    result = self._get_result(document, *args, **kwargs)
  File "C:\Users\Zabraf\AppData\Local\Programs\Python\Python310\lib\site-packages\wandb\vendor\gql-0.2.0\wandb_gql\client.py", line 60, in _get_result
    return self.transport.execute(document, *args, **kwargs)
  File "C:\Users\Zabraf\AppData\Local\Programs\Python\Python310\lib\site-packages\wandb\vendor\gql-0.2.0\wandb_gql\transport\requests.py", line 38, in execute
    request = requests.post(self.url, **post_args)
  File "C:\Users\Zabraf\AppData\Local\Programs\Python\Python310\lib\site-packages\requests\api.py", line 115, in post
    return request("post", url, data=data, json=json, **kwargs)
  File "C:\Users\Zabraf\AppData\Local\Programs\Python\Python310\lib\site-packages\requests\api.py", line 59, in request
    return session.request(method=method, url=url, **kwargs)
  File "C:\Users\Zabraf\AppData\Local\Programs\Python\Python310\lib\site-packages\requests\sessions.py", line 587, in request
    resp = self.send(prep, **send_kwargs)
  File "C:\Users\Zabraf\AppData\Local\Programs\Python\Python310\lib\site-packages\requests\sessions.py", line 701, in send
    r = adapter.send(request, **kwargs)
  File "C:\Users\Zabraf\AppData\Local\Programs\Python\Python310\lib\site-packages\requests\adapters.py", line 565, in send
    raise ConnectionError(e, request=request)
requests.exceptions.ConnectionError: HTTPConnectionPool(host='localhost', port=8080): Max retries exceeded with url: /graphql (Caused by NewConnectionError('<urllib3.connection.HTTPConnection object at 0x0000024E180B5810>: Failed to establish a new connection: [WinError 10061] Aucune connexion n’a pu être établie car l’ordinateur cible l’a expressément refusée'))
2022-11-11 17:20:49,118 DEBUG   HandlerThread:14200 [handler.py:handle_request():138] handle_request: poll_exit
2022-11-11 17:20:54,233 DEBUG   HandlerThread:14200 [handler.py:handle_request():138] handle_request: poll_exit
